<mujocoinclude>
  <body name="link_base" pos="0.5 0.5 0" euler="0 0 3.1416">
    <geom quat="1 0 0 0" type="mesh" mesh="link_base" name="link_base" contype="0" conaffinity="0"/>


    <!-- link1 -->
    <body name="link1" pos="0 0 0.267" quat="1 0 0 0">
      <inertial pos="0.00022 0.02951 -0.0124" 
                quat="0.687496 -0.167758 -0.692973 0.137823" 
                mass="2.3814" 
                diaginertia="0.00312315 0.00544434 0.00585697"/>
      <joint name="joint1" pos="0 0 0" axis="0 0 1" limited="true" 
             range="-31.41592653589793 31.41592653589793"/>
      <geom name="link1" type="mesh" mesh="link1" pos="0 0 0" quat="1 0 0 0"/>


      <!-- link2 -->
      <body name="link2" pos="0 0 0" quat="0.707106 -0.707106 0 0">
        <inertial pos="0.03881 -0.22783 0.03496"
                  quat="0.354540 -0.784399 0.344760 -0.374379"
                  mass="2.2675"
                  diaginertia="0.00383449 0.02817832 0.02944767"/>
        <joint name="joint2" pos="0 0 0" axis="0 0 1" limited="true"
               range="-31.41592653589793 31.41592653589793"/>
        <geom name="link2" type="mesh" mesh="link2" pos="0 0 0" quat="1 0 0 0"/>


        <!-- link3 -->
        <body name="link3" pos="0.0535 -0.2845 0" quat="1 0 0 0">
          <inertial pos="0.07041 0.11631 0.0107"
                    quat="0.394500 -0.390789 0.207303 -0.805406"
                    mass="1.875"
                    diaginertia="0.00196753 0.00699471 0.00714132"/>
          <joint name="joint3" pos="0 0 0" axis="0 0 1" limited="true"
                 range="-31.41592653589793 31.41592653589793"/>
          <geom name="link3" type="mesh" mesh="link3" pos="0 0 0" quat="1 0 0 0"/>


          <!-- link4 -->
          <body name="link4" pos="0.0775 0.3425 0" quat="0.707105 -0.707108 0 0">
            <inertial pos="-0.00018 0.01798 -0.02291"
                      quat="0.021184 0.705336 -0.031100 -0.707874"
                      mass="1.3192"
                      diaginertia="0.00132609 0.00447403 0.00489614"/>
            <joint name="joint4" pos="0 0 0" axis="0 0 1" limited="true"
                   range="-31.41592653589793 31.41592653589793"/>
            <geom name="link4" type="mesh" mesh="link4" pos="0 0 0" quat="1 0 0 0"/>
            

            <!-- link5 -->
            <body name="link5" pos="0 0 0" quat="0.707105 0.707108 0 0">
              <inertial pos="0.0651 0.03096 0.00315"
                        quat="0.951392 0.0443623 0.139403 0.271019"
                        mass="1.33854"
                        diaginertia="0.00108731 0.00213367 0.00241824"/>
              <joint name="joint5" pos="0 0 0" axis="0 0 1" limited="true"
                     range="-31.41592653589793 31.41592653589793"/>
              <geom name="link5" type="mesh" mesh="link5" pos="0 0 0" quat="1 0 0 0"/>
              

              <!-- link6 -->
              <body name="link6" pos="0.076 0.097 0" quat="0.707105 -0.707108 0 0">
                <inertial pos="0 -0.00677 -0.01098"
                          quat="0.706895 0.017307 0.017307 -0.706895"
                          mass="0.17"
                          diaginertia="5.85236e-05 9.30000e-05 1.32176e-04"/>
                <joint name="joint6" pos="0 0 0" axis="0 0 1" limited="true"
                      range="-31.41592653589793 31.41592653589793"/>
                <geom name="link6" type="mesh" mesh="link6" pos="0 0 0" quat="1 0 0 0"/>


                <!-- Gripper base -->
                <!-- <body name="gripper_base_link" pos="0 0 0" quat="1 0 0 0">
                  <inertial pos="-0.00065489 -0.0018497 0.048028"
                            quat="0.0503981 0.700898 0.0510734 0.709643"
                            mass="0.54156"
                            diaginertia="0.00025480 0.00033231 0.00047109"/>
                  <geom type="mesh" mesh="gripper_base_mesh" pos="0 0 0" quat="1 0 0 0"/>
                </body> -->
              </body>
            </body>
          </body>
        </body>
      </body>
    </body>
  </body>
</mujocoinclude>

